Workbook

Sheet Summary
A1: #VALUE!
A3: Summary of Projects
A4: Date: | B4: =TODAY() -> 46058
B6: Project Count | C6: Contract Amount | D6: Gross Amnt TD Invoiced | E6: Aged Receivables | F6: Received | G6: Contract Backlog
A7: Commercial
A8: Active | B8: =Commercial!C84-Commercial!C82 -> 15 | C8: =Commercial!D84-Commercial!D82 -> 21709122 | D8: =Commercial!E84-Commercial!E82 -> 14872622 | E8: =Commercial!G84-Commercial!G82 -> 1279679.5 | F8: =Commercial!L39 -> 13580240 | G8: =Commercial!J84-Commercial!J82 -> 6836500.3
A9: Completed * | B9: =Commercial!C86 -> 16 | C9: =Commercial!D86 -> 7078105.8 | D9: =Commercial!E86 -> 7012831.2 | E9: =Commercial!G86 -> 0 | F9: =D9 -> 7012831.2 | G9: =Commercial!J86 -> 65274.55
B10: Sub Total: | C10: =SUM(C8:C9) -> 28787228 | D10: =SUM(D8:D9) -> 21885453 | E10: =SUM(E8:E9) -> 1279679.5 | F10: =SUM(F8:F9) -> 20593071 | G10: =SUM(G8:G9) -> 6901774.8
A12: Residential
A13: Active | B13: =Residential!C120-Residential!C118 -> 13 | C13: =Residential!D120-Residential!D118 -> 316891.98 | D13: =Residential!E120-Residential!E118 -> 168293.64 | E13: =Residential!G120-Residential!G118 -> 39773.59 | F13: =Residential!H120-Residential!H118 -> 128520.05 | G13: =Residential!J120-Residential!J118 -> 148598.34
A14: Completed * | B14: =Residential!C122 -> 48 | C14: =Residential!D122 -> 1284794.6 | D14: =Residential!E122 -> 1284228.2 | E14: =Residential!G122 -> 66569.76 | F14: =Residential!H122 -> 1217658.4 | G14: =Residential!J122 -> 566.43
B15: Sub Total: | C15: =SUM(C13:C14) -> 1601686.6 | D15: =SUM(D13:D14) -> 1452521.8 | E15: =SUM(E13:E14) -> 106343.35 | F15: =SUM(F13:F14) -> 1346178.5 | G15: =SUM(G13:G14) -> 149164.77
A17: Repairs
A18: Active | B18: =Repairs!C121-Repairs!C119 -> 1 | C18: =Repairs!D121-Repairs!D119 -> 12000 | D18: =Repairs!E121-Repairs!E119 -> 12000 | E18: =Repairs!F121-Repairs!F119 -> 0 | F18: =Repairs!H121-Repairs!H119 -> 12000 | G18: =Repairs!I121-Repairs!I119 -> 0
A19: Completed* | B19: =Repairs!C123 -> 47 | C19: =Repairs!D123 -> 241356.67 | D19: =Repairs!E123 -> 230921.67 | E19: =Repairs!F123 -> 4625 | F19: =Repairs!H123 -> 228796.67 | G19: =Repairs!I123 -> 10435
B20: Sub Total: | C20: =SUM(C18:C19) -> 253356.67 | D20: =SUM(D18:D19) -> 242921.67 | E20: =SUM(E18:E19) -> 4625 | F20: =SUM(F18:F19) -> 240796.67 | G20: =SUM(G18:G19) -> 10435
A22: Maintenance
A23: Active | B23: =Maintenance!C114-Maintenance!C112 -> 0 | C23: =Maintenance!D114-Maintenance!D112 -> 0 | D23: =Maintenance!E114-Maintenance!E112 -> 0 | E23: =Maintenance!F114-Maintenance!F112 -> 0 | F23: =Maintenance!H114-Maintenance!H112 -> 0 | G23: =Maintenance!I114-Maintenance!I112 -> 0
A24: Completed* | B24: =Maintenance!C116 -> 34 | C24: =Maintenance!D116 -> 199047.5 | D24: =Maintenance!E116 -> 142197.5 | E24: =Maintenance!F116 -> 42995.5 | F24: =Maintenance!H116 -> 108202 | G24: =Maintenance!I116 -> 56850
B25: Sub Total: | C25: =SUM(C23:C24) -> 199047.5 | D25: =SUM(D23:D24) -> 142197.5 | E25: =SUM(E23:E24) -> 42995.5 | F25: =SUM(F23:F24) -> 108202 | G25: =SUM(G23:G24) -> 56850
A27: Grand Totals: | B27: Active | C27: =SUM(C8,C13,C18,C23) -> 22038014 | D27: =SUM(D8,D13,D18,D23) -> 15052915 | E27: =SUM(E8,E13,E18,E23) -> 1319453 | F27: =SUM(F8,F13,F18,F23) -> 13720760 | G27: =SUM(G8,G13,G18,G23) -> 6985098.6
B28: Completed | C28: =SUM(C9,C14,C19,C24) -> 8803304.6 | D28: =SUM(D9,D14,D19,D24) -> 8670178.6 | E28: =SUM(E9,E14,E19,E24) -> 114190.26 | F28: =SUM(F9,F14,F19,F24) -> 8567488.3 | G28: =SUM(G9,G14,G19,G24) -> 133125.98

Sheet Commercial
A1: Commercial Projects
B2: Date: | C2: =TODAY() -> 46058
B3: Active Commercial Projects
C5: Commercial Projects | M5: Date: | N5: =TODAY() -> 46058
B6: Active Commercial Projects
B7: Job Name | C7: Type of Work | D7: Supervisor | E7: Salesperson | G7: Project Status | H7: Contract Signed | J7: Contract Amount | K7: Invoiced to Date | L7: Received to Date | M7: Aged Receivables | N7: % of Contract Invoiced | O7: Backlog | P7: Notes | Q7: NTO | Z7: Project Status
B8: Leisure Beach S. Condo 2900 Banyan St., Ft. Lauderdale, Fl 33316 | C8: SPF | D8: AJ | E8: Shawn | G8: In Process | H8: Yes | J8: 135500 | K8: 151228.44 | L8: 118031.1 | M8: 33197.34 | N8: =K8/J8 -> 1.116077 | O8: =J8-K8 -> -15728.44 | P8: Inv no 43811 - $30,448.00 - Temp Roofing - emailed on 10/28/25, inv no 43869 - Permit Fees - $2749.34 - emailed on 11/26/25 | Q8: YES
B9: Palm Beach Yacht Center 7848 S. Federal Hwy., Lantana, Fl 33462 | C9: SPF | D9: Scott | E9: Scott | G9: In Process | H9: Yes | J9: 282237 | K9: 84671.1 | L9: 84671.1 | M9: 0 | N9: =K9/J9 -> 0.3 | O9: =J9-K9 -> 197565.9 | P9: Not started | Q9: YES
B10: Geraldo Abreu - Deer Run 2 4301 Coral Springs Drive Coral Springs, FL 33065 | C10: Tile | D10: AJ | E10: Santiago | G10: In Process | H10: Yes | J10: 174382.54 | K10: 8719.13 | L10: 8719.13 | M10: 0 | N10: =K10/J10 -> 0.050000017 | O10: =J10-K10 -> 165663.41 | P10: Not started | Q10: YES
B11: Lime Bay Condominium 9190 Lime Bay Blvd Tamarac, FL 33321 | C11: SPF | D11: AJ | E11: Scott | G11: In Process | H11: Yes | J11: 1479799 | K11: 570755.1 | L11: 434380.3 | M11: 136374.8 | N11: =K11/J11 -> 0.38569772 | O11: =J11-K11 -> 909043.9 | P11: Inv no 43941- $136,374.80 - Pay App no 5 - 40% of Commencement - BUILDING 15 - 9401 Lime Bay Blvd / C/O # 3: 1 ea. AC Repairs and Line Jack Install. | Q11: YES | Z11: Not Started
B12: Brian Tansey / Worth Avenue Yachts 866 NE 20th Avenue Ft. Lauderdale, Fl 33304-3223 | C12: SPF/Flat | D12: AJ | E12: Santiago | G12: Completed | H12: Yes | J12: 41372.5 | K12: 41372.5 | M12: 0 | N12: =K12/J12 -> 1 | O12: =J12-K12 -> 0 | Q12: Yes | Z12: Completed
B13: Protech E2 103375 Oversees Hwy, Key Largo, FL 33037 | C13: Foam | D13: AJ | E13: Scott | G13: Completed | H13: Yes | J13: 34752 | K13: 34752 | M13: 0 | N13: =K13/J13 -> 1 | O13: =J13-K13 -> 0 | Q13: YES | Z13: Delayed
B14: Alpine Woods Condo 9600 Griffin Road, Cooper City, FL 33328 | C14: SPF | D14: AJ | E14: Scott | G14: In Process | H14: Yes | J14: 1379892.8 | K14: 1511348 | L14: 1298987.6 | M14: 199658.09 | N14: =K14/J14 -> 1.0952648 | O14: =J14-K14 -> -131455.22 | P14: REPAIRS - $2,197.25- (Inv no 43514-$570.00- sent 6/25/25, , Inv no 43645 - $477.25 - sent 8/25/25, Inv no 43646 - $575.00 - sent 8/25/25, Inv no 43647 - $575.00 - sent 8/25/25), COMMERCIAL - $197,460.84 - (Inv no 43886 - $130,545.00 - Wood bill (bill may be reduced by 50% as per Scott) - presently on hold as per Scott to meet w/ Alpine Wood), Inv no 43945 - $66,915.84 - Pay App no 36 - emailed on 1/6/26 | Q14: YES | R14: MIsc reve. $178797.47 -
B15: Admiral Towers 1020 Meridian Avenue Miami Beach, Fl 33139 | C15: SPF | D15: AJ | E15: Shawn | G15: In Process | H15: Yes | J15: 439157.47 | K15: 513937.13 | L15: 383848.42 | M15: 130088.71 | N15: =K15/J15 -> 1.1702798 | O15: =J15-K15 -> -74779.66 | P15: TEMP ROOFING - $28,217.22 - (Inv no 43833 - $28,217.22 emailed on 11/11/25),COMMERCIAL - $101,871.49 ( Inv no 43891 - $101,871.49 - 20% due upon 50% Completion and Final 50% Billing for Change Order no 2 & 3 - emailed on 12/11/25) | Q15: YES
B16: Regal Trace Ltd 540 NW 4th Ave, Fort Lauderdale, FL 33311 | C16: Shingle | D16: AJ | E16: Scott | G16: Completed | H16: Yes | J16: 1945117.7 | K16: 1852763.3 | M16: 0 | N16: =K16/J16 -> 0.95251986 | O16: =J16-K16 -> 92354.47 | Q16: NO | AE16: Regal Trace Ltd 540 NW 4th Ave Fort Lauderdale, FL 33111 954-468-1800
B17: Holy Acres Pet Resort | C17: Foam | D17: AJ | E17: Scott | G17: Completed | H17: Yes | J17: 25000 | K17: 25000 | N17: =K17/J17 -> 1 | O17: =J17-K17 -> 0 | Q17: NO | Z17: Litigation
B18: Westview Condominium 3 9142 Limetree Ln, Pembroke Pines FL 33024 | C18: Modified | D18: AJ | E18: Shawn | G18: In Process | H18: Yes | J18: 639307.8 | K18: 400443.4 | L18: 400443.4 | M18: 0 | N18: =K18/J18 -> 0.62637027 | O18: =J18-K18 -> 238864.4 | Q18: Yes | Z18: Pending
B19: High Point Court Ass., Inc. 211 High Point Blvd, Boynton Beach, FL 33445 | C19: Shingle | D19: Blake | E19: Shawn | G19: In Process | H19: Yes | J19: 608732.7 | K19: 645337.48 | L19: 542930.6 | M19: 102406.88 | N19: =K19/J19 -> 1.0601328 | O19: =J19-K19 -> -36604.78 | P19: Inv no 43878 - $51,917.00 - Pay app no 7 -emailed on 12/8/25 , Inv no 43955 - $50,489.88 - Pay app no 9 -emailed on 1/6/26 s/b billed in full per Scott | Q19: YES
B20: Lakeside Village 500 Lori Drive Palm Springs, Fl 33461 | C20: Shingle | D20: Blake | E20: Shawn | G20: In Process | H20: Yes | J20: 7849873.5 | K20: 5116010.8 | L20: 4780664.5 | M20: =9834.62+325511.68 -> 335346.3 | N20: =K20/J20 -> 0.65173162 | O20: =J20-K20 -> 2733862.7 | P20: EXTRA WORK - Inv no. 43626 - $9,834.62 - Repairs performed due to roof leak caused by The Cool Team (A/C contractor) - Client: Adriana Dilworth, COMMERCIAL - Inv no 43940 - $325,511.68 | Q20: YES
B21: Island Crest Condominium 10680 S. Ocean Drive Jensen Beach, Fl 34957 | C21: SPF | D21: Blake | E21: David | G21: In Process | H21: Yes | J21: 568634 | K21: 596906.11 | L21: 526787.6 | M21: 70118.51 | N21: =K21/J21 -> 1.0497193 | O21: =J21-K21 -> -28272.11 | P21: COMMERCIAL - $70,118.51 - Inv no 43809- $22,500.00 - Temp Roofing - emailed 10/28/25 - Update Amount of Invoice to $22,500.00 as per SCI Agreement and Inv no 43936 - Final Bill - not paid yet but have copy of check for payment | Q21: YES
B22: High Point of Delray 292 High Point Blvd, Delray Beach, FL 33445 | C22: Shingle Peel & Stick | D22: Blake | E22: Shawn | G22: In Process | H22: Yes | J22: 2113635.7 | K22: 2132834.7 | L22: 2113634.7 | M22: 19200 | N22: =K22/J22 -> 1.0090834 | O22: =J22-K22 -> -19199 | P22: Inv no 43892 - $19,200.00 - Wood Bill - Pay App no 11:s/b another approx. $50k for addl woodwork | Q22: YES
B23: KAPS-ALL Packaging Systems 251 N Congress Avenue, Delray Beach, Fl 33445 | C23: SPF | D23: Blake | E23: Shawn | G23: In Process | H23: Yes | J23: 181000 | K23: 36200 | L23: 36200 | M23: 0 | N23: =K23/J23 -> 0.2 | O23: =J23-K23 -> 144800 | Q23: YES
B24: The Land of President 2500-3050 Presidential Way, West Palm Beach | C24: SPF | D24: Blake | E24: Shawn | G24: In Process | H24: Yes | J24: 457084 | K24: 22854.2 | L24: 22854.2 | M24: 0 | N24: =K24/J24 -> 0.05 | O24: =J24-K24 -> 434229.8 | Q24: YES
B25: Mark One Condominium 1050 SE 15th Street Ft. Lauderdale, Fl 33316 | C25: SPF/Flat | D25: AJ | E25: Garry | G25: Completed | H25: Yes | J25: 109450 | K25: 109450 | N25: =K25/J25 -> 1 | O25: =J25-K25 -> 0 | Q25: YES
B26: Lauderdale West | C26: Tile | D26: Shawn | E26: Scott | G26: In Process | H26: Yes | J26: 2362972.5 | K26: 1672943.6 | L26: 1641437.3 | M26: 31506.3 | N26: =K26/J26 -> 0.70798268 | O26: =J26-K26 -> 690028.9 | P26: Wood Bills: $2,000.00 | Q26: NO | AE26: Lauderdale West
B27: Greensward Village | C27: Shingle | D27: David | E27: EJ | G27: Completed | H27: Yes | J27: 1590731 | K27: 1617810.9 | M27: 0 | N27: =K27/J27 -> 1.0170236 | O27: =J27-K27 -> -27079.92 | Q27: NO | Z27: No Contract | AE27: Greensward Village 745 Greenward Ct. Delray Beach, FL 33069 954-984-1000
B28: Isles of Boca Association 23229 Fountain View Drive Boca Raton, Fl 33433 | C28: Tile | D28: Blake | E28: Shawn | G28: Litigation | H28: Yes | J28: 3036913 | K28: 1408432.5 | L28: 1186650 | M28: 221782.52 | N28: =K28/J28 -> 0.46377112 | O28: =J28-K28 -> 1628480.5 | P28: 14 - $115,670.72 - sent on 3/21/25, 15 - $105,703.32 - originally emailed on 3/28/25 - revised sent on 4/25/25, 16 - on Hold, Fees - inv no 43327- $408.50 - 4/9/25 | Q28: YES
B29: Mariner's Way Condo 2707 14th Street Causeway Pompano Beach, Fl 33062 | C29: SPF | D29: AJ | E29: Shawn | G29: Completed | H29: Yes | J29: 89533.47 | K29: 89533.47 | N29: =K29/J29 -> 1 | O29: =J29-K29 -> 0 | Q29: YES | Z29: In Process
B30: Amkin Mgmt-Bainbridge | C30: Recoat / SPF | D30: Scott | E30: Scott | G30: Completed | H30: Yes | J30: 1100000 | K30: 1100000 | N30: =K30/J30 -> 1 | O30: =J30-K30 -> 0 | Q30: NO | Z30: STATUS LEGEND: | AE30: Amkin Mgmt-Bainbridge 1501 Colquitt Bainbridge, GA
B31: Amkin Mgmt-Flamingo Seafood | C31: TPO | D31: AJ | E31: Scott | G31: Completed | H31: Yes | J31: 26880 | K31: 26880 | N31: =K31/J31 -> 1 | O31: =J31-K31 -> 0 | Q31: NO | Z31: In Process | AE31: Amkin Mgmt-Flamingo Seafood 2798 E Atlantic Blvd. Pompano Beach, FL 32062
B32: Amkin Mgmt-Westbay | C32: Recoat | D32: Scott | E32: Scott | G32: Completed | H32: Yes | J32: 74380 | K32: 74380 | N32: =K32/J32 -> 1 | O32: =J32-K32 -> 0 | Q32: NO | Z32: POSTPONED | AE32: Amkin Mgmt-Westbay 311 W Bay Street Jacksonville, FL 32202
B33: Meadowbrook Tower L | C33: SPF | D33: Shawn | E33: Shawn | G33: Completed | H33: Yes | J33: 206716.13 | K33: 206716.13 | N33: =K33/J33 -> 1 | O33: =J33-K33 -> 0 | AE33: Meadowbrook Tower L 319 NE 14 Avenue Hallandale, FL 33009 416-453-7996
B34: Casa Blanca Condominiums 701 NE 1st Court Hallandale, Fl 33009 | C34: SPF | D34: AJ | E34: Shawn | G34: Completed | H34: Yes | J34: 315441.97 | K34: 315441.97 | N34: =K34/J34 -> 1 | O34: =J34-K34 -> 0 | Q34: YES
B35: Winston Towers 400 | C35: SPF | D35: Shawn | E35: Shawn | G35: Completed | H35: Yes | J35: 1106726 | K35: 1106726 | N35: =K35/J35 -> 1 | O35: =J35-K35 -> 0 | AE35: Donnil Kenney 3095 S Military Trail Lake Worth, FL 33463 561-644-0077
B36: Donnil Kenney | C36: SPF | D36: Garry | E36: Scott | G36: Completed | H36: Yes | J36: 170825 | K36: 170825 | N36: =K36/J36 -> 1 | O36: =J36-K36 -> 0
B37: The Field - British Oak | C37: Shingle & Flat | D37: Garry | E37: Garry | G37: Completed | H37: Yes | J37: 97150 | K37: 97150 | N37: =K37/J37 -> 1 | O37: =J37-K37 -> 0 | AE37: The Field - British Oak 3281 Griffin Road Fort Lauderdale, Florida 33312 954-649-6082 Marie McMullen
B38: Regency Island Dunes | C38: SPF N. Bldg Porta Cochere Metal - S. Bldg | D38: David | E38: David | G38: Completed | H38: Yes | J38: 144030 | K38: 144030 | N38: =K38/J38 -> 1 | O38: =J38-K38 -> 0 | AE38: Regency Island Dunes 8640/8650 S Ocean Dr Jensen Beach, FL 34957
H39: Totals | J39: =SUM(J8:J38) -> 28787228 | K39: =SUM(K8:K38) -> 21885453 | L39: =SUM(L8:L38) -> 13580240 | M39: =SUM(M22,M26,M8,M11,M14,M15:M21) -> 1057896.9 | O39: =SUM(O8:O38) -> 6901774.8
B78: Commercial Projects | C78: Project Count | D78: Contract Amount | E78: Gross Amnt TD Invoiced | G78: Outstanding Invoice Amnt | H78: Gross Amnt Paid | J78: Contract Amnt Not Invoiced
B79: Projects In Process: | C79: =COUNTIF($G$8:$G$38,"In Process") -> 14 | D79: =SUMIF($G$8:$G$38,"In Process",J$8:J$38) -> 18672209 | E79: =SUMIF($G$8:$G$38,"In Process",K$8:K$38) -> 13464189 | G79: =SUMIF($G$8:$G$38,"In Process",M$8:M$38) -> 1057896.9 | H79: =SUMIF($G$8:$G$38,"In Process",#REF!) -> #REF! | J79: =SUMIF($G$8:$G$38,"In Process",O$8:O$38) -> 5208019.8
...

Sheet Residential
A1: Residential Projects
B2: Date: | C2: =TODAY() -> 46058
B3: Active Residential Projects
B5: Project Info. | G5: Project Status | J5: Project Bookkeeping | P5: Comments | Q5: NTO
J6: Gross Amnt Invoiced: | K6: =E120-E118 -> 168293.64 | L6: <-Active Projects Amnts-> | N6: Gross Outstanding Invoiced Amnt: | O6: =G120-G118 -> 39773.59
B7: Job Name | C7: Type of Work | D7: Supervisor | E7: Salesperson | G7: Project Status | H7: Contract Signed | J7: Contract Amount | K7: Gross Amnt TD Invoiced | L7: Outstanding Invoice Amnt | M7: Gross Amnt Paid | N7: % of Contract Invoiced | O7: Contract Amnt Not Invoiced | Z7: Project Status
B8: Darrylle Hood 3549 SW 14th St, Ft Lauderdale, FL 33312 | C8: Shingle | D8: AJ | E8: Shawn | G8: Completed | H8: Yes | J8: 18022.4 | K8: 0 | L8: 0 | M8: =K8-L8 -> 0 | N8: =K8/J8 -> 0 | O8: =J8-K8 -> 18022.4 | Q8: YES
B9: Jason Finch 565 Holly Drive, Palm Beach Gardens, Fl 33410 | C9: Shingle | D9: Shawn | E9: Shawn | G9: In Process | H9: Yes | J9: 16403.14 | K9: 16403.14 | L9: 0 | M9: 16403.14 | N9: 1 | O9: =J9-K9 -> 0 | P9: Ygrene Financing Paid
B10: MAURICE PIETRACULPA Boynton leisureville | C10: SPF ROOF RECOVERING | D10: Repairs | E10: Terry | G10: Pending | H10: Yes | J10: 9000 | K10: 0 | L10: 0 | M10: 0 | N10: 0 | O10: =J10-K10 -> 9000 | Q10: Louis foam truck scheduled for 1/31/26
B11: Daniel Poliseo 12399 NW 80th Place, Parkland, Fl 33076 | C11: Foam - Seam Tape | D11: AJ | E11: Santiago | G11: In Process | H11: Yes | J11: 48726.81 | K11: 9745.36 | L11: 0 | M11: =K11-L11 -> 9745.36 | N11: =K11/J11 -> 0.19999996 | O11: =J11-K11 -> 38981.45
B12: Monica Gonzalez Zuniga 5835 TARRAGON DR, WEST PALM BEACH, FL, 33415 | C12: SPF Foam Flat Roof | D12: Blake | E12: Terry | G12: In Process | H12: Yes | J12: 27868.09 | K12: 0 | L12: 0 | M12: =K12-L12 -> 0 | N12: =K12/J12 -> 0 | O12: =J12-K12 -> 27868.09 | P12: Credit Approved by Renew Financial
B13: Scott Stoik 26201 SW 167 Avenue, Homestead, Fl 33031 | C13: SPF Foam Flat Roof | D13: AJ | E13: Santiago | G13: In Process | H13: Yes | J13: 34334.12 | K13: 34334.12 | L13: 13733.65 | M13: =K13-L13 -> 20600.47 | N13: =K13/J13 -> 1 | O13: =J13-K13 -> 0 | P13: Billed for 20% deposit and 40% upon commenecement Paid in Full, Billed for 40% upon completion on 1/27/2026 not paid yet
B14: Mike Feingold 9325 SW 16th Rd W, Boca Raton, Fl 33428 | C14: Modified Roof System | D14: Garry | E14: Garry | G14: Completed | H14: Yes | J14: 5000 | K14: 5690.69 | L14: 0 | M14: =K14-L14 -> 5690.69 | N14: =K14/J14 -> 1.138138 | O14: =J14-K14 -> -690.69
B15: G.K. Windows Treatments 231 SW 5th Street, Pompano Beach, Fl 33069 | C15: SPF Roof System | D15: Garry | E15: Garry | G15: Completed | H15: Yes | J15: 90000 | K15: 93670.38 | L15: 39670.38 | M15: =K15-L15 -> 54000 | N15: =K15/J15 -> 1.040782 | O15: =J15-K15 -> -3670.38 | P15: Inv no 43950 - $39,670.38 - Final bill and Permit Fees
B16: David Gross 3864 NW 63rd Terrace Coral Springs, Fl 33067 | C16: Tiles | D16: AJ | E16: Santiago | G16: In Process | H16: Yes | J16: 25174.32 | K16: 5034.86 | L16: 0 | M16: =K16-L16 -> 5034.86 | N16: =K16/J16 -> 0.19999984 | O16: =J16-K16 -> 20139.46
B17: Annisha Armoogan 6420 Oak Street, Hollywood, Fl 33024 | C17: Shingle | D17: AJ | E17: Santiago | G17: Completed | H17: Yes | J17: 11601.45 | K17: 12410.7 | L17: 0 | M17: =K17-L17 -> 12410.7 | N17: =K17/J17 -> 1.0697542 | O17: =J17-K17 -> -809.25
B18: Lou Ann Banks 408 NE 9th Avenue, Ft. Lauderdale. Fl 33301 | E18: Garry | G18: Completed | H18: Yes | J18: 33900 | K18: 33900 | L18: 0 | M18: =K18-L18 -> 33900 | N18: =K18/J18 -> 1 | O18: =J18-K18 -> 0 | P18: inv no 43885 - Final Bill
B19: Lynn Silverman 911 NE Sandalwood Place, Jensen Beach, Fl 34957 | C19: Shingle | D19: Blake | E19: Santiago | G19: Completed | H19: Yes | J19: 14435.66 | K19: 14861.04 | L19: 0 | M19: =K19-L19 -> 14861.04 | N19: =K19/J19 -> 1.0294673 | O19: =J19-K19 -> -425.38
B20: Joe Simmons 7627 SW 102 Place, Miami, Fl 33173 | C20: SPF | D20: AJ | E20: Scott | G20: Completed | H20: Yes | J20: 23700 | K20: 23700 | L20: 14220 | M20: =K20-L20 -> 9480 | N20: =K20/J20 -> 1 | O20: =J20-K20 -> 0 | P20: Inv no 43928 - $14220.00 - Final Bill
B21: Jordan Schilt 3725 Piedmont Street Hollywood, Fl 33021 | C21: Tile | D21: AJ | E21: Santiago | G21: In Process | H21: Yes | J21: 18825.5 | K21: 11295.3 | L21: 0 | M21: =K21-L21 -> 11295.3 | N21: =K21/J21 -> 0.6 | O21: =J21-K21 -> 7530.2 | P21: inv no 43907 - $7,530.20 - 40% Upon Commencement - emailed on 12/17/25- Awaiting payment status from HOA association since Jordan has moved from community and is no longer with the HOA
B22: Christina Fry 584 SW 131st Ave, Davie, fL 33325 | C22: Shingle | D22: AJ | E22: Santiago | G22: Delayed | H22: Yes | J22: 10085 | K22: 0 | L22: 0 | M22: =K22-L22 -> 0 | N22: =K22/J22 -> 0 | O22: =J22-K22 -> 10085 | P22: On Hold, No Money
B23: Jim Balistreri 321 SE 15th Avenue Deerfield, Fl 33441 | C23: SPF | D23: AJ | E23: Garry | G23: Completed | H23: Yes | J23: 41000 | K23: 45947.1 | L23: 0 | M23: =K23-L23 -> 45947.1 | N23: =K23/J23 -> 1.120661 | O23: =J23-K23 -> -4947.1
B24: Lauderdale West: James & Virginia Holman 8217 NW 15 Ct. Plantation, Fl 33322 | C24: Tiles | D24: Shawn | E24: Shawn | G24: Completed | H24: Yes | J24: 5850 | K24: 5850 | L24: 0 | M24: =K24-L24 -> 5850 | N24: =K24/J24 -> 1 | O24: =J24-K24 -> 0
B25: Peter Chesky 1171 Faieview Ln, West Palm Beach | C25: Metal Aluminum | D25: Blake | E25: Santiago | G25: In Process | H25: Yes | J25: 60799.85 | K25: 45119.94 | L25: 24319.94 | M25: =K25-L25 -> 20800 | N25: =K25/J25 -> 0.74210611 | O25: =J25-K25 -> 15679.91 | P25: Billed for 30% deposit (paid) and 40% upon completion (unpaid) on 01/27/2026
B26: Jack English Lake Worth Country Club 5279 Fountain Dr. S. Lake Worth, Fl 33467 | C26: Modified Bitumen | D26: Blake | E26: Garry | G26: Completed | H26: Yes | J26: 32675 | K26: 32675 | L26: 0 | M26: =K26-L26 -> 32675 | N26: =K26/J26 -> 1 | O26: =J26-K26 -> 0
B27: Anthony Santilli 5130 NW 57th Way Coral Springs, Fl 33067 | C27: Tile | D27: AJ | E27: Shawn | G27: In Process | H27: Yes | J27: 35541 | K27: 23150 | L27: 0 | M27: =K27-L27 -> 23150 | N27: =K27/J27 -> 0.6513604 | O27: =J27-K27 -> 12391
B28: Charles Graves 531 NE 39th Street, Deerfield Beach, Fl 33064 | C28: Shingles | D28: AJ | E28: Shawn | G28: Completed | H28: Yes | J28: 9938.4 | K28: 9938.4 | L28: 0 | M28: =K28-L28 -> 9938.4 | N28: =K28/J28 -> 1 | O28: =J28-K28 -> 0
B29: Jennifer & David Hickman D/D Lobster Company Inc. 16032 Prestwich Dr. E, Loxahatchee, FL 33470 | C29: Shingle | D29: Blake | E29: Scott/Blake | G29: Completed | H29: Yes | J29: 13066.07 | K29: 13066.07 | L29: 0 | M29: =K29-L29 -> 13066.07 | N29: =K29/J29 -> 1 | O29: =J29-K29 -> 0
B30: Carol Cutillo 19631 Delaware Cricle, Boca Raton, Fl 19631 | C30: Shingle | D30: Blake | E30: Joshua | G30: Completed | H30: Yes | J30: 11612.47 | K30: 11612.47 | L30: 0 | M30: =K30-L30 -> 11612.47 | N30: =K30/J30 -> 1 | O30: =J30-K30 -> 0
B31: Marie J. Leo 6329 Cleveland Street Hollywood, Fl 33024 | C31: SPF Foam Flat Roof | D31: AJ | E31: Santiago | G31: Pending | H31: Yes | J31: 17795.45 | K31: 10872.22 | L31: 1100 | M31: =K31-L31 -> 9772.22 | N31: =K31/J31 -> 0.61095505 | O31: =J31-K31 -> 6923.23 | P31: 12 Month Payment Plan - 5 of 12 payments - Client made payment 4 of 12) - inv no: 43930- $1,100.00 - emailed 12/23/25, 1/20/26
B32: Anisha Eckroth 2288 Gabriel Lane West Palm Beach, Fl 33406 | C32: Roof Repair | D32: Blake | E32: Santiago | G32: Pending | H32: Yes | J32: 950 | K32: 950 | L32: 200 | M32: =K32-L32 -> 750 | N32: =K32/J32 -> 1 | O32: =J32-K32 -> 0 | P32: inv no 43700 - $200.00, Payment arrangement for $950.00 @ $200.00 bi-weekly billing until full contract amount is paid full
B33: Desmond Arscott 4410 NE 3rd Avenue Pompano Beach, Fl 33064 | C33: Shingle | D33: AJ | E33: Garry | G33: Completed | H33: Yes | J33: 9210 | K33: 9210 | L33: 0 | M33: =K33-L33 -> 9210 | N33: =K33/J33 -> 1 | O33: =J33-K33 -> 0
B34: Clover Williams 3188 La Mirage Drive Lauderhill, Fl 33319 | C34: Tile | D34: AJ | E34: Santiago | G34: Completed | H34: Yes | J34: 25605 | K34: 25605 | L34: 0 | M34: =K34-L34 -> 25605 | N34: =K34/J34 -> 1 | O34: =J34-K34 -> 0 | P34: Warranty and ROL
B35: Lisa Sawin 637 56th Street West Palm Beach, Fl 33407 | C35: Shingle | D35: Blake | E35: Santiago | G35: Completed | H35: Yes | J35: 8983.65 | K35: 9721.15 | L35: 0 | M35: =K35-L35 -> 9721.15 | N35: =K35/J35 -> 1.0820936 | O35: =J35-K35 -> -737.5 | P35: Warranty and ROL
B36: Shelly-Ann M. Knight 8811 Cleary Blvd Plantation, Fl 33324 | C36: Shingles | D36: AJ | E36: Santiago | G36: Completed | H36: Yes | J36: 10237.68 | K36: 10237.68 | L36: 0 | M36: =K36-L36 -> 10237.68 | N36: =K36/J36 -> 1 | O36: =J36-K36 -> 0 | P36: Warranty and ROL
B37: Eneida Werner 11719 Timbers Way Boca Raton, Fl 33428 | C37: Shingle | D37: Blake | E37: Joshua | G37: Pending | H37: Yes | J37: 11388.7 | K37: 11388.7 | L37: 420 | M37: =K37-L37 -> 10968.7 | N37: =K37/J37 -> 1 | O37: =J37-K37 -> 0 | P37: 5 Month Payment Plan - invoice no 43775 - $210.00 - 4 of 5 - emailed on 10/14/25 - invoice no 43908 - $210.00 - 5 of 5 - emailed on 12/17/25
B38: Helen Stern 2232 SW 33rd Way Fort Lauderdale, Fl 33312 | C38: SPF Roof System | D38: Shawn | E38: Shawn | G38: Completed | H38: Yes | J38: 28962 | K38: 28962 | L38: 0 | M38: =K38-L38 -> 28962 | N38: =K38/J38 -> 1 | O38: =J38-K38 -> 0
B39: Lora Delorenzo 816 Blueberry Drive, Wellington, Fl 33414 | C39: Shingle | D39: David | E39: Joshua | G39: Completed | H39: Yes | J39: 22416.4 | K39: 22416.4 | L39: 0 | M39: =K39-L39 -> 22416.4 | N39: =K39/J39 -> 1 | O39: =J39-K39 -> 0
B40: Marco Lopez-Calleja 2538 Bahia Road, West Palm Beach, Fl 33408 | C40: Shingle | D40: Blake | E40: Garry | G40: Completed | H40: Yes | J40: 16117.47 | K40: 16117.47 | L40: 0 | M40: =K40-L40 -> 16117.47 | N40: =K40/J40 -> 1 | O40: =J40-K40 -> 0 | P40: Warranty and ROL
B41: Mark Hosang 3375 Sw 2nd Ct. Deerfield Beach, Fl 33442 | C41: Shingle | D41: AJ | E41: Joshua | G41: Completed | H41: Yes | J41: 28102.73 | K41: 28102.74 | L41: 0 | M41: =K41-L41 -> 28102.74 | N41: =K41/J41 -> 1.0000004 | O41: =J41-K41 -> -0.01
...

Sheet Repairs
A1: Repairs
B2: Date: | C2: =TODAY() -> 46058
B3: Active Repair Projects
B5: Repairs Info. | H5: Repair Status | K5: Repairs Bookkeeping | Q5: Comments | R5: NTO
K6: Gross Amnt Invoiced: | L6: =E121-E119 -> 12000 | M6: <-Active Projects Amnts-> | O6: Gross Outstanding Invoiced Amnt: | P6: =F121-F119+F123 -> 4625
B7: Job Name | C7: Type of Work | D7: Category | E7: Supervisor | F7: Salesperson | H7: Project Status | I7: Contract Signed | K7: Contract Amount | L7: Gross Amnt TD Invoiced | M7: Outstanding Invoice Amnt | N7: Gross Amnt Paid | O7: % of Contract Invoiced | P7: Contract Amnt Not Invoiced | AA7: Project Status
B8: Courtyard Marriott Hotel Coral springs 620 n University Dr | C8: Repair | D8: Repairs | E8: Gabriella | F8: Scott | H8: Completed | I8: Yes | K8: 11000 | L8: 11000 | M8: 11000 | N8: 5500 | O8: =L8/K8 -> 1 | P8: =K8-L8 -> 0 | Q8: completed 1/23/26 50% paid awaiting on Noor to inform terry when check can be picked up this week
B9: MAX CHANG 934 Bluewood Terrace, Weston, FL 33327 | C9: Repair Roof Leak | D9: Repairs | E9: Gabriella | F9: Santiago | H9: Completed | I9: Yes | K9: 1712.25 | L9: 1712.25 | M9: 0 | N9: =L9-M9 -> 1712.25 | O9: =L9/K9 -> 1 | P9: =K9-L9 -> 0 | Q9: paid in full
B10: MAX CHANG 934 Bluewood Terrace, Weston, FL 33327 | C10: Repair Roof Leak | D10: Repairs | E10: Gabriella | F10: Santiago | H10: Completed | I10: Yes | K10: 950 | L10: 950 | M10: 0 | N10: =L10-M10 -> 950 | O10: =L10/K10 -> 1 | P10: =K10-L10 -> 0 | Q10: Paid in full 10/27/25
B11: Chateau at Boca Grove 7383 Orangewood lane Boca Raton, FL 33433 | C11: Repair Roof Leak | D11: Repairs | E11: Gabriella | F11: Garry | H11: Completed | I11: yes | K11: 1200 | L11: 1200 | M11: 0 | N11: =L11-M11 -> 1200 | O11: =L11/K11 -> 1 | P11: =K11-L11 -> 0 | Q11: paid in full 10/3/25
B12: Chateau at Boca Grove 7383 Orangewood lane Boca Raton, FL 33433 | C12: Repair Roof Leak | D12: Repairs | E12: Gabriella | F12: Garry | H12: Completed | I12: Yes | K12: 5300 | L12: 5300 | M12: 0 | N12: =L12-M12 -> 5300 | O12: =L12/K12 -> 1 | P12: =K12-L12 -> 0 | Q12: paid in full 11/5/25
B13: Amelia Guerra 1250 NE 125th Street North Miami, Fl 33161 | C13: Repair Roof Leak | D13: Repairs | E13: Gabriella | F13: Santiago | H13: Completed | I13: Yes | K13: 6800 | L13: 6800 | M13: 0 | N13: =L13-M13 -> 6800 | O13: =L13/K13 -> 1 | P13: =K13-L13 -> 0 | Q13: paid in full 10/31/25
B14: Skymark Real Estate Office 1540 s federal hwy pompano beach fl 33062 | C14: Repair Roof Leak | D14: Repairs | E14: Garry | F14: Garry | H14: Completed | I14: yes | K14: 1500 | L14: 1500 | M14: 0 | N14: =L14-M14 -> 1500 | O14: =L14/K14 -> 1 | P14: =K14-L14 -> 0 | Q14: completed 11/3/25 invoice 43823 paid in full 11/18/25
B15: Ryan Patch 2172 Queen Palm Road Boca Raton, Fl 33432 | C15: Repair Roof Leak | D15: Repairs | E15: Gabriella | F15: Santiago | H15: Completed | I15: Yes | K15: 1200 | L15: 1200 | M15: 0 | N15: =L15-M15 -> 1200 | O15: =L15/K15 -> 1 | P15: =K15-L15 -> 0 | Q15: paid in full 10/3/25
B16: Starlight Towers 6000 N Ocean Blvd. Lauderdale-by-the-sea, Fl 33308 | C16: Repair | D16: Repairs | E16: Garry | F16: Garry | H16: Completed | I16: Yes | K16: 5310 | L16: 0 | M16: 0 | N16: =L16-M16 -> 0 | O16: =L16/K16 -> 0 | P16: =K16-L16 -> 5310 | Q16: PAID IN FULL AS OF 11/4/25
B17: Starlight Towers 6000 N Ocean Blvd. Lauderdale-by-the-sea, Fl 33308 | C17: REPAIR | D17: Repairs | E17: Garry | F17: GARRY | H17: Completed | I17: YES | K17: 2360 | L17: 2360 | M17: 0 | N17: =L17-M17 -> 2360 | O17: =L17/K17 -> 1 | P17: =K17-L17 -> 0 | Q17: WORK COMPLETED 11/4/25 INV 43822 PAYMENT date 11/21/25
B18: MARKETPLACE BSO OFFICE2926 N ST RD 7 OAKLAND PARK | C18: Repair Roof Leak | D18: Repairs | E18: Gabriella | F18: Garry | H18: Completed | I18: YES | K18: 2500 | L18: 0 | M18: 0 | N18: 2500 | O18: 1 | P18: =K18-L18 -> 2500 | Q18: completed 12/22/25 awaiting payment
B19: Sam Levine 6644 Patio LN | C19: repair | D19: Repairs | E19: Gabriella | F19: Garry | H19: Completed | I19: Yes | K19: 2334 | L19: 2334 | M19: 0 | N19: =L19-M19 -> 2334 | O19: =L19/K19 -> 1 | P19: =K19-L19 -> 0 | Q19: paid in full
B20: Casablanca Isles Boynton beach | C20: Repair | D20: Repairs | E20: Gabriella | F20: Gabriella | H20: Completed | I20: Yes | K20: 1895 | L20: 1895 | M20: 0 | N20: =L20-M20 -> 1895 | O20: =L20/K20 -> 1 | P20: =K20-L20 -> 0 | Q20: PAID IN FULL 10/21/25
B21: JCI-2460 PGA Blvd. | E21: EJ | F21: Garry | H21: Litigation | I21: No | K21: 12000 | L21: 12000 | M21: 0 | N21: =L21-M21 -> 12000 | O21: =L21/K21 -> 1 | P21: =K21-L21 -> 0 | Q21: Under Litigation | R21: YES
B22: Meadowbrook L 319 NE 14 Ave Hallandale Beach 33009 | C22: Repair | D22: Repairs | E22: Gabriella | F22: Garry | H22: Completed | I22: No Contract | K22: 250 | L22: 250 | M22: 250 | N22: =L22-M22 -> 0 | O22: =L22/K22 -> 1 | P22: =K22-L22 -> 0 | Q22: service charge, no roof leaks - Meadowbrook will not pay invoice
B23: Embassy Park Condo 1700 Embassy Dr WPB | C23: Repair | D23: Repairs | E23: Garry | F23: Garry | H23: Completed | I23: No Contract | K23: 250 | L23: 250 | M23: 0 | N23: =L23-M23 -> 250 | O23: =L23/K23 -> 1 | P23: =K23-L23 -> 0 | Q23: PAID IN FULL 9/29/25
B24: Variety Foods 1300 SW 2nd St | C24: Repair Roof Leak | D24: Repairs | E24: garry | F24: garry | H24: Completed | I24: Yes | K24: 3595 | L24: 3595 | M24: 0 | N24: =L24-M24 -> 3595 | O24: =L24/K24 -> 1 | P24: =K24-L24 -> 0 | Q24: paidin full 9/23/25
B25: Nationwide loan consultants | C25: repair Roof Leak | D25: Repairs | E25: Garry | F25: Garry | H25: Completed | I25: Yes | K25: 2900 | L25: 2900 | M25: 0 | N25: =L25-M25 -> 2900 | O25: =L25/K25 -> 1 | P25: =K25-L25 -> 0 | Q25: paid in full 9/11/25
B26: Galt Ocean Terrace | C26: Repair/change order | D26: Repairs | E26: Garry | F26: Scott | H26: Completed | I26: Yes | K26: 16747.5 | L26: 16747.5 | M26: 0 | N26: =L26-M26 -> 16747.5 | O26: =L26/K26 -> 1 | P26: =K26-L26 -> 0 | Q26: PAID IN FULL PLUS 1100 EXTRA WORK CHARGE
B27: Xavier Doe 1210 Van Buren Street, Hollywood, Fl 33019 | C27: Repair | D27: Repairs | E27: Gabriella | F27: Santiago | H27: Completed | I27: Yes | K27: 1000 | L27: 1000 | M27: 0 | N27: =L27-M27 -> 1000 | O27: =L27/K27 -> 1 | P27: =K27-L27 -> 0 | Q27: PAID IN FULL 8/14/25
B28: Yvette & Shaun 9146 Pinto Dr Wellignton | C28: Repair Roof Leak | D28: Repairs | E28: Gabriella | F28: Gabriella | H28: Completed | I28: Yes | K28: 2200 | L28: 2200 | M28: 0 | N28: =L28-M28 -> 2200 | O28: =L28/K28 -> 1 | P28: =K28-L28 -> 0 | Q28: PAID IN FULL 8/22/25
B29: Geneva Group Jennafer Belabin 1015 North State Road 7, Royal Palm Beach, fl 33411 | C29: Repair | D29: Repairs | E29: Gabriella | F29: Santiago | H29: Completed | I29: Yes | K29: 1645.15 | L29: 1645.15 | M29: 0 | N29: =L29-M29 -> 1645.15 | O29: =L29/K29 -> 1 | P29: =K29-L29 -> 0 | Q29: PAID IN FULL
B30: Jill Moss 1 Seneca Rd, Sea Ranch Lakes | C30: Main./Repair | D30: Repairs | E30: Santiago | F30: Santiago | H30: Completed | I30: Yes | K30: 2456.37 | L30: 2456.37 | M30: 0 | N30: =L30-M30 -> 2456.37 | O30: =L30/K30 -> 1 | P30: =K30-L30 -> 0 | Q30: PAID IN FULL 7/22/25
B31: Krystina Wright - Prestigious Property Management 2405 Lake Drive, Riviera Beach, Fl 33404 | C31: Repair | D31: Repairs | E31: Gabriella | F31: Santiago | H31: Completed | I31: Yes | K31: 2168.35 | L31: 2168.35 | M31: 0 | N31: =L31-M31 -> 2168.35 | O31: =L31/K31 -> 1 | P31: =K31-L31 -> 0 | Q31: PAID IN FULL 7/18/25
B32: Rick Howard Havana Dr Boca Ration | C32: Repair | D32: Repairs | E32: Garry | F32: Garry | H32: Completed | I32: Yes | K32: 900 | L32: 900 | M32: 0 | N32: =L32-M32 -> 900 | O32: =L32/K32 -> 1 | P32: =K32-L32 -> 0 | Q32: PAID IN FULL
B33: Rick Howard Havana Dr Boca Ration | C33: Repair | D33: Repairs | E33: Garry | F33: Garry | H33: Completed | I33: Yes | K33: 2972 | L33: 2972 | M33: 0 | N33: =L33-M33 -> 2972 | O33: =L33/K33 -> 1 | P33: =K33-L33 -> 0 | Q33: PAID IN FULL
... B36: Galt Ocean Terrace | C36: Main./Repair | D36: Repairs | E36: Garry | F36: Scott | H36: Completed | I36: Yes | K36: 19168 | L36: 19168 | M36: 0 | N36: =L36-M36 -> 19168 | O36: =L36/K36 -> 1 | P36: =K36-L36 -> 0 | Q36: PAID IN FULL
B37: Regent Park Condo 1900 Van Buren Street Hollywood, Fl 33020 | C37: Foam | D37: Repairs | E37: Scott | F37: Scott | H37: Completed | I37: Yes | K37: 34125 | L37: 34125 | M37: 0 | N37: =L37-M37 -> 34125 | O37: =L37/K37 -> 1 | P37: =K37-L37 -> 0 | Q37: PAID IN FULL | W37: Pressure Clean
B38: Regent Park Condo 1900 Van Buren Street Hollywood, Fl 33020 | C38: Foam | D38: Repairs | E38: Scott | F38: Scott | H38: Completed | I38: Yes | K38: 58000 | L38: 58000 | M38: 0 | N38: =L38-M38 -> 58000 | O38: =L38/K38 -> 1 | P38: =K38-L38 -> 0 | Q38: job completed 6.10.25 paid in full | W38: Repairs
B39: Regent Park Condo 1900 Van Buren Street Hollywood, Fl 33020 | C39: Foam | D39: Repairs | E39: Scott | F39: Scott | H39: Completed | I39: Yes | K39: 6500 | L39: 6500 | M39: 0 | N39: =L39-M39 -> 6500 | O39: =L39/K39 -> 1 | P39: =K39-L39 -> 0 | Q39: PAID IN FULL | W39: Warranty
B40: Casablanca Isles Boynton beach | C40: 3 roof repairs | D40: Repairs | E40: Shawn | F40: Santiago | H40: Completed | I40: Yes | K40: 5925.3 | L40: 5925.3 | M40: 0 | N40: =L40-M40 -> 5925.3 | O40: =L40/K40 -> 1 | P40: =K40-L40 -> 0 | Q40: completed and paid
B41: Onclave Boca Dunes 10214 Akenside Drive Boca Raton, Fl 33428 | C41: Tile repairs | D41: Repairs | E41: Shawn | F41: Santiago | H41: Completed | I41: Yes | K41: 1085.3 | L41: 1085.3 | M41: 0 | N41: =L41-M41 -> 1085.3 | O41: =L41/K41 -> 1 | P41: =K41-L41 -> 0 | Q41: completed and paid
B42: Gerald Legow - 4 | C42: Repair Roof Leak | D42: Repairs | E42: Gary | F42: Gary | H42: Completed | I42: Yes | K42: 250 | L42: 0 | M42: 0 | N42: =L42-M42 -> 0 | O42: =L42/K42 -> 0 | P42: =K42-L42 -> 250 | Q42: PAID IN FULL
B43: Bob Porter | C43: SPF over Flat Roof | D43: Repairs | E43: Garry | F43: Garry | H43: Completed | I43: Yes | K43: 4150 | L43: 4150 | M43: 0 | N43: =L43-M43 -> 4150 | O43: =L43/K43 -> 1 | P43: =K43-L43 -> 0 | Q43: PAID IN FULL
...

Sheet Maintenance
A1: Maintenance
B2: Date: | C2: =TODAY() -> 46058
B3: Active Maintenance Projects
B5: Maintenance Info. | H5: Maint. Status | K5: Maintenance Bookkeeping | Q5: Comments | R5: NTO
K6: Gross Amnt Invoiced: | L6: =E114-E112 -> 0 | M6: <-Active Projects Amnts-> | O6: Gross Outstanding Invoiced Amnt: | P6: =F114-F112+F116 -> 42995.5
B7: Job Name | C7: Type of Work | D7: Category | E7: Supervisor | F7: Salesperson | H7: Project Status | I7: Contract Signed | K7: Contract Amount | L7: Gross Amnt TD Invoiced | M7: Outstanding Invoice Amnt | N7: Gross Amnt Paid | O7: % of Contract Invoiced | P7: Contract Amnt Not Invoiced | AA7: Project Status
B8: Cheryl Newton | C8: Pressue Clean | D8: Pressure Clean | E8: Gabriella | F8: Gabriella | H8: Completed | I8: Yes | K8: 450 | L8: 450 | M8: 0 | N8: =L8-M8 -> 450 | O8: =L8/K8 -> 1 | P8: =K8-L8 -> 0 | Q8: PAID IN FULL | R8: YES
B9: Kim Cronin | C9: Maintenance | D9: Warranty | E9: Garry | F9: Garry | H9: Completed | I9: Yes | K9: 1200 | L9: 1200 | M9: 0 | N9: =L9-M9 -> 1200 | O9: =L9/K9 -> 1 | P9: =K9-L9 -> 0 | Q9: PAID IN FULL
B10: Aisha Eckroth | C10: Maintenance | D10: Gabriella | E10: Gabriella | F10: Santiago | H10: Completed | I10: Yes | K10: 950 | L10: 950 | M10: 550 | N10: =L10-M10 -> 400 | O10: =L10/K10 -> 1 | P10: =K10-L10 -> 0 | Q10: financing 200$ per Santiagio contract terms
B11: Peggy Salomone | C11: Pressure Wash/Recoat | D11: Warranty | E11: Garry | F11: Garry | H11: Completed | I11: yes | K11: 3000 | L11: 3000 | M11: 0 | N11: =L11-M11 -> 3000 | O11: =L11/K11 -> 1 | P11: =K11-L11 -> 0 | Q11: PAID IN FULL
B12: Tradewinds Condo Assn | C12: Maintenance | D12: Warranty | E12: Gabriella | F12: Gabriella | H12: Completed | I12: Yes | K12: 6000 | L12: 6000 | M12: 0 | N12: =L12-M12 -> 6000 | O12: =L12/K12 -> 1 | P12: =K12-L12 -> 0 | Q12: PAID IN FULL
B13: Marseilles Court at the Fountains | C13: Maintenance | D13: Warranty | E13: Gabriella | F13: Gabriella | H13: Completed | I13: Yes | K13: 13104 | L13: 13104 | M13: 0 | N13: =L13-M13 -> 13104 | O13: =L13/K13 -> 1 | P13: =K13-L13 -> 0 | Q13: PAID IN FULL
B14: Tom Jeffers | C14: Maintenance | D14: Pressure Clean | E14: Garry | F14: Garry | H14: Completed | I14: Yes | K14: 3900 | L14: 3900 | M14: 0 | N14: =L14-M14 -> 3900 | O14: =L14/K14 -> 1 | P14: =K14-L14 -> 0 | Q14: PAID IN FULL
B15: Robert & Rose (Luke Residence) | C15: Pressure Wash/Recoat | D15: Warranty | E15: Garry | F15: Gabriella | H15: Completed | I15: Yes | K15: 5100 | L15: 5100 | M15: 0 | N15: =L15-M15 -> 5100 | O15: =L15/K15 -> 1 | P15: =K15-L15 -> 0 | Q15: PAID IN FULL 8/12/25
B16: Starlight Towers | C16: Maintenance | D16: Pressure Clean | E16: Garry | F16: Garry | H16: Completed | I16: Yes | K16: 6510 | L16: 6510 | M16: 0 | N16: =L16-M16 -> 6510 | O16: =L16/K16 -> 1 | P16: =K16-L16 -> 0 | Q16: PAID IN FULL 8/13/25
B17: ANTHONY RAWSON | C17: Maintenance | E17: Garry | F17: Garry | H17: Completed | I17: YES | K17: 4600 | L17: 4600 | M17: 0 | N17: =L17-M17 -> 4600 | O17: =L17/K17 -> 1 | P17: =K17-L17 -> 0 | Q17: Need to pick up check
B18: Seagate @ Gulfstream | C18: Maintenance | D18: Warranty | E18: Gabriella | F18: Gabriella | H18: Completed | I18: Yes | K18: 3500 | L18: 3500 | M18: 0 | N18: =L18-M18 -> 3500 | O18: =L18/K18 -> 1 | P18: =K18-L18 -> 0 | Q18: Inv no 43560 - Roof Maintenance
B19: Perry Klimas | C19: Pressure Wash | D19: Warranty | E19: Gabriella | F19: Gabriella | H19: Completed | I19: Yes | K19: 450 | L19: 450 | M19: 0 | N19: =L19-M19 -> 450 | O19: =L19/K19 -> 1 | P19: =K19-L19 -> 0 | Q19: Inv no 43597 - Gen. Roof cleaning
B20: Parkview Point Condos | C20: Maintenance | D20: Warranty | E20: Garry | F20: Garry | H20: Completed | I20: Yes | K20: 4600 | L20: 0 | M20: 0 | N20: =L20-M20 -> 0 | O20: =L20/K20 -> 0 | P20: =K20-L20 -> 4600 | Q20: paid in full 9/19/25
B21: Berger Commercial Realty JMA Investment 2075-2197 North Powerline Rd. Pompano Beach, FL 33069 | C21: Pressure wash | E21: Gabriella | F21: Scott | H21: Completed | I21: yes | K21: 23691 | L21: 23691 | M21: 11845.5 | N21: =L21-M21 -> 11845.5 | O21: =L21/K21 -> 1 | P21: =K21-L21 -> 0 | Q21: 50% balance due awating check payment
B22: Berger Commercial Realty Marketplace plaza 3662-3704 West Oakland Park | C22: pressue wash | E22: Gabriella | F22: Scott | H22: Completed | I22: Yes | K22: 32000 | L22: 16000 | M22: 16000 | N22: =L22-M22 -> 0 | O22: 1 | P22: =K22-L22 -> 16000 | Q22: pending completion
B23: Portabella Townhomes 780 Jeffery Street Boca Raton, FL 33487 | C23: Maintenance | D23: Pressure Clean | E23: Garry | F23: Garry | H23: Completed | I23: Yes | K23: 5500 | L23: 5500 | M23: 0 | N23: =L23-M23 -> 5500 | O23: =L23/K23 -> 1 | P23: =K23-L23 -> 0 | Q23: paid in full 10/3/25
B24: Darlene & Jorge | C24: Maintenance | D24: Warranty | E24: Gabriella | F24: Santiago | H24: Completed | I24: yes | K24: 18992.5 | L24: 18992.5 | M24: 0 | N24: =L24-M24 -> 18992.5 | O24: =L24/K24 -> 1 | P24: =K24-L24 -> 0 | Q24: PAID IN FULL 8/10/25
B25: Ed & Pamela 6341 NE 15 AVE FORT LAUDERDALE, FL 33334 | C25: Pressure Wash/Recoat | D25: Warranty | E25: Garry | F25: Gabriella | H25: Completed | I25: Yes | K25: 8975 | L25: 8975 | M25: 0 | N25: =L25-M25 -> 8975 | O25: =L25/K25 -> 1 | P25: =K25-L25 -> 0 | Q25: paid in full 10/20/25
B26: Palm Aire Condo #6 (Patio Homes) | C26: Maintenance | D26: Warranty | E26: Gabriella | F26: Gabriella | H26: Completed | I26: Yes | K26: 0 | L26: 0 | M26: 0 | N26: =L26-M26 -> 0 | O26: 0.5 | P26: =K26-L26 -> 0 | Q26: invoiced 50% deposit payment pending 9/4/25 | W26: Pressure Clean
B27: Palm Aire Condo #6 (Villas) | C27: Maintenance | D27: Warranty | E27: Gabriella | F27: Gabriella | H27: Completed | I27: yes | K27: 3800 | L27: 1600 | M27: 0 | N27: =L27-M27 -> 1600 | O27: 0.5 | P27: =K27-L27 -> 2200 | Q27: invoiced 50% deposit payment pending 9/4/25 | W27: Repairs
B28: Palm Aire Condo #6 (Building 78A) | C28: Maintenance | D28: Warranty | E28: Gabriella | F28: Gabriella | H28: Completed | I28: yes | K28: 3900 | L28: 0 | M28: 0 | N28: =L28-M28 -> 0 | O28: 0.5 | P28: =K28-L28 -> 3900 | Q28: invoiced 50% deposit payment pending 9/4/25 | W28: Warranty
B29: Palm Aire Condo #6 (Building 77) | C29: Maintenance | D29: Warranty | E29: Gabriella | F29: Gabriella | H29: Completed | I29: yes | K29: 3900 | L29: 0 | M29: 0 | N29: =L29-M29 -> 0 | O29: 0.5 | P29: =K29-L29 -> 3900 | Q29: invoiced 50% deposit payment pending 9/4/25
B30: Palm Aire Condo #6 (Building 76) | C30: Maintenance | D30: Warranty | E30: Gabriella | F30: Gabriella | H30: Completed | I30: yes | K30: 3900 | L30: 0 | M30: 0 | N30: =L30-M30 -> 0 | O30: 0.5 | P30: =K30-L30 -> 3900 | Q30: invoiced 50% deposit payment pending 9/4/25
B31: Palm Aire Condo #6 (Building 75) | C31: Maintenance | D31: Warranty | E31: Gabriella | F31: Gabriella | H31: Completed | I31: yes | K31: 2900 | L31: 0 | M31: 0 | N31: =L31-M31 -> 0 | O31: 0.5 | P31: =K31-L31 -> 2900 | Q31: invoiced 50% deposit payment pending 9/4/25
B32: Palm Aire Condo #6 (Building 74) | C32: Maintenance | D32: Warranty | E32: Gabriella | F32: Gabriella | H32: Completed | I32: yes | K32: 2900 | L32: 0 | M32: 0 | N32: =L32-M32 -> 0 | O32: 0.5 | P32: =K32-L32 -> 2900 | Q32: invoiced 50% deposit payment pending 9/4/25
B33: Palm Aire Condo #6 (Building 73) | C33: Maintenance | D33: Warranty | E33: Gabriella | F33: Gabriella | H33: Completed | I33: yes | K33: 2900 | L33: 0 | M33: 0 | N33: =L33-M33 -> 0 | O33: 0.5 | P33: =K33-L33 -> 2900 | Q33: invoiced 50% deposit payment pending 9/4/25
B34: Palm Aire Condo #6 (Building 72) | C34: Maintenance | D34: Warranty | E34: Gabriella | F34: Gabriella | H34: Completed | I34: yes | K34: 3900 | L34: 0 | M34: 0 | N34: =L34-M34 -> 0 | O34: 0.5 | P34: =K34-L34 -> 3900 | Q34: invoiced 50% deposit payment pending 9/4/25
B35: Palm Aire Condo #6 (Building 71) | C35: Maintenance | D35: Warranty | E35: Gabriella | F35: Gabriella | H35: Completed | I35: yes | K35: 2900 | L35: 0 | M35: 0 | N35: =L35-M35 -> 0 | O35: 0.5 | P35: =K35-L35 -> 2900 | Q35: invoiced 50% deposit payment pending 9/4/25
B36: Palm Aire Condo #6 (Building 70) | C36: Maintenance | D36: Warranty | E36: Gabriella | F36: Gabriella | H36: Completed | I36: yes | K36: 3900 | L36: 0 | M36: 0 | N36: =L36-M36 -> 0 | O36: 0.5 | P36: =K36-L36 -> 3900 | Q36: invoiced 50% deposit payment pending 9/4/25
B37: Cypress Creek Condos | C37: Maintenance | D37: Warranty | E37: Gabriella | F37: Scott | H37: Completed | I37: yes | K37: 2950 | L37: 0 | M37: 0 | N37: =L37-M37 -> 0 | O37: =L37/K37 -> 0 | P37: =K37-L37 -> 2950 | Q37: project not started yet
B38: Coral Gables Granda | C38: Maintenance | D38: Warranty | E38: Gabriella | F38: Scott | H38: Completed | I38: yes | K38: 5600 | L38: 5600 | M38: 5600 | N38: =L38-M38 -> 0 | O38: =L38/K38 -> 1 | P38: =K38-L38 -> 0 | Q38: awaiting payment
B39: Country Club Towers Coral Springs | C39: Maintenance | E39: Gabreilla | F39: Scott | H39: Completed | I39: yes | K39: 3600 | L39: 3600 | M39: 0 | N39: =L39-M39 -> 3600 | O39: =L39/K39 -> 1 | P39: =K39-L39 -> 0 | Q39: project not started yet
B40: Patricia Chichester 908 SW 6 Ave boynton beach | C40: roof cleaning | E40: Gabriella | F40: Gabriella | H40: Completed | I40: yes | K40: 475 | L40: 475 | M40: 0 | N40: =L40-M40 -> 475 | O40: =L40/K40 -> 1 | P40: =K40-L40 -> 0 | Q40: paid in full 9/19/25
B41: Patricia Chichester 908 SW 6 Ave boynton beach | C41: Maintenance | E41: Gabriella | F41: Terry | H41: Completed | I41: Yes | K41: 9000 | L41: 9000 | M41: 9000 | N41: 9000 | O41: 1 | P41: 0 | Q41: contract signed 1/5/26 paid 50% deposit 50% balance paid with CC 1/29/26
...
